<?xml version="1.0" encoding="UTF-8"?>
<testng-results skipped="1" failed="1" ignored="0" total="4" passed="2">
  <reporter-output>
  </reporter-output>
  <suite name="Default suite" duration-ms="42" started-at="2020-05-26T07:39:45Z" finished-at="2020-05-26T07:39:45Z">
    <groups>
    </groups>
    <test name="Default test" duration-ms="42" started-at="2020-05-26T07:39:45Z" finished-at="2020-05-26T07:39:45Z">
      <class name="Demo_TestNG.Demo_TestNG.TC_Login_DOM">
        <test-method status="FAIL" signature="TC_Login_01()[pri:0, instance:Demo_TestNG.Demo_TestNG.TC_Login_DOM@26653222]" name="TC_Login_01" duration-ms="9" started-at="2020-05-26T07:39:45Z" finished-at="2020-05-26T07:39:45Z">
          <exception class="java.lang.Exception">
            <message>
              <![CDATA[Intentionally]]>
            </message>
            <full-stacktrace>
              <![CDATA[java.lang.Exception: Intentionally
at Demo_TestNG.Demo_TestNG.TC_Login_DOM.TC_Login_01(TC_Login_DOM.java:11)
at sun.reflect.NativeMethodAccessorImpl.invoke0(Native Method)
at sun.reflect.NativeMethodAccessorImpl.invoke(Unknown Source)
at sun.reflect.DelegatingMethodAccessorImpl.invoke(Unknown Source)
at java.lang.reflect.Method.invoke(Unknown Source)
at org.testng.internal.MethodInvocationHelper.invokeMethod(MethodInvocationHelper.java:124)
at org.testng.internal.Invoker.invokeMethod(Invoker.java:583)
at org.testng.internal.Invoker.invokeTestMethod(Invoker.java:719)
at org.testng.internal.Invoker.invokeTestMethods(Invoker.java:989)
at org.testng.internal.TestMethodWorker.invokeTestMethods(TestMethodWorker.java:125)
at org.testng.internal.TestMethodWorker.run(TestMethodWorker.java:109)
at org.testng.TestRunner.privateRun(TestRunner.java:648)
at org.testng.TestRunner.run(TestRunner.java:505)
at org.testng.SuiteRunner.runTest(SuiteRunner.java:455)
at org.testng.SuiteRunner.runSequentially(SuiteRunner.java:450)
at org.testng.SuiteRunner.privateRun(SuiteRunner.java:415)
at org.testng.SuiteRunner.run(SuiteRunner.java:364)
at org.testng.SuiteRunnerWorker.runSuite(SuiteRunnerWorker.java:52)
at org.testng.SuiteRunnerWorker.run(SuiteRunnerWorker.java:84)
at org.testng.TestNG.runSuitesSequentially(TestNG.java:1208)
at org.testng.TestNG.runSuitesLocally(TestNG.java:1137)
at org.testng.TestNG.runSuites(TestNG.java:1049)
at org.testng.TestNG.run(TestNG.java:1017)
at org.testng.remote.AbstractRemoteTestNG.run(AbstractRemoteTestNG.java:114)
at org.testng.remote.RemoteTestNG.initAndRun(RemoteTestNG.java:251)
at org.testng.remote.RemoteTestNG.main(RemoteTestNG.java:77)
]]>
            </full-stacktrace>
          </exception> <!-- java.lang.Exception -->
          <reporter-output>
          </reporter-output>
        </test-method> <!-- TC_Login_01 -->
        <test-method status="PASS" signature="TC_Login_03()[pri:0, instance:Demo_TestNG.Demo_TestNG.TC_Login_DOM@26653222]" name="TC_Login_03" duration-ms="2" started-at="2020-05-26T07:39:45Z" finished-at="2020-05-26T07:39:45Z">
          <reporter-output>
          </reporter-output>
        </test-method> <!-- TC_Login_03 -->
        <test-method status="PASS" signature="TC_Login_04()[pri:0, instance:Demo_TestNG.Demo_TestNG.TC_Login_DOM@26653222]" name="TC_Login_04" duration-ms="1" started-at="2020-05-26T07:39:45Z" finished-at="2020-05-26T07:39:45Z">
          <reporter-output>
          </reporter-output>
        </test-method> <!-- TC_Login_04 -->
        <test-method status="SKIP" signature="TC_Login_02()[pri:0, instance:Demo_TestNG.Demo_TestNG.TC_Login_DOM@26653222]" name="TC_Login_02" duration-ms="0" started-at="2020-05-26T07:39:45Z" depends-on-methods="Demo_TestNG.Demo_TestNG.TC_Login_DOM.TC_Login_01" finished-at="2020-05-26T07:39:45Z">
          <exception class="java.lang.Throwable">
            <message>
              <![CDATA[Method TC_Login_DOM.TC_Login_02()[pri:0, instance:Demo_TestNG.Demo_TestNG.TC_Login_DOM@26653222] depends on not successfully finished methods]]>
            </message>
            <full-stacktrace>
              <![CDATA[java.lang.Throwable: Method TC_Login_DOM.TC_Login_02()[pri:0, instance:Demo_TestNG.Demo_TestNG.TC_Login_DOM@26653222] depends on not successfully finished methods
at org.testng.internal.Invoker.invokeTestMethods(Invoker.java:888)
at org.testng.internal.TestMethodWorker.invokeTestMethods(TestMethodWorker.java:125)
at org.testng.internal.TestMethodWorker.run(TestMethodWorker.java:109)
at org.testng.TestRunner.privateRun(TestRunner.java:648)
at org.testng.TestRunner.run(TestRunner.java:505)
at org.testng.SuiteRunner.runTest(SuiteRunner.java:455)
at org.testng.SuiteRunner.runSequentially(SuiteRunner.java:450)
at org.testng.SuiteRunner.privateRun(SuiteRunner.java:415)
at org.testng.SuiteRunner.run(SuiteRunner.java:364)
at org.testng.SuiteRunnerWorker.runSuite(SuiteRunnerWorker.java:52)
at org.testng.SuiteRunnerWorker.run(SuiteRunnerWorker.java:84)
at org.testng.TestNG.runSuitesSequentially(TestNG.java:1208)
at org.testng.TestNG.runSuitesLocally(TestNG.java:1137)
at org.testng.TestNG.runSuites(TestNG.java:1049)
at org.testng.TestNG.run(TestNG.java:1017)
at org.testng.remote.AbstractRemoteTestNG.run(AbstractRemoteTestNG.java:114)
at org.testng.remote.RemoteTestNG.initAndRun(RemoteTestNG.java:251)
at org.testng.remote.RemoteTestNG.main(RemoteTestNG.java:77)
]]>
            </full-stacktrace>
          </exception> <!-- java.lang.Throwable -->
          <reporter-output>
          </reporter-output>
        </test-method> <!-- TC_Login_02 -->
      </class> <!-- Demo_TestNG.Demo_TestNG.TC_Login_DOM -->
    </test> <!-- Default test -->
  </suite> <!-- Default suite -->
</testng-results>
